<?xml version="1.0"?>
<robot name="simple_arm_v1">
  <link name="base_link">
    <inertial>
      <origin xyz="0 0 0.05" rpy="0 0 0"/>
      <mass value="2.0"/>
      <inertia ixx="0.01" ixy="0" ixz="0" iyy="0.01" iyz="0" izz="0.01"/>
    </inertial>
    <visual>
      <origin xyz="0 0 0.05" rpy="0 0 0"/>
      <geometry><box size="0.2 0.2 0.1"/></geometry>
    </visual>
  </link>

  <link name="link_1">
    <inertial>
      <origin xyz="0 0 0.15" rpy="0 0 0"/>
      <mass value="1.0"/>
      <inertia ixx="0.0083" ixy="0" ixz="0" iyy="0.0083" iyz="0" izz="0.0001"/>
    </inertial>
    <visual>
      <origin xyz="0 0 0.15" rpy="0 0 0"/>
      <geometry><cylinder length="0.3" radius="0.03"/></geometry>
    </visual>
  </link>

  <link name="link_2">
    <inertial>
      <origin xyz="0 0 0.125" rpy="0 0 0"/>
      <mass value="0.5"/>
      <inertia ixx="0.0042" ixy="0" ixz="0" iyy="0.0042" iyz="0" izz="0.00005"/>
    </inertial>
    <visual>
      <origin xyz="0 0 0.125" rpy="0 0 0"/>
      <geometry><cylinder length="0.25" radius="0.02"/></geometry>
    </visual>
  </link>

  <link name="ee_link">
    <inertial>
      <origin xyz="0 0 0.025" rpy="0 0 0"/>
      <mass value="0.1"/>
      <inertia ixx="0.00001" ixy="0" ixz="0" iyy="0.00001" iyz="0" izz="0.00001"/>
    </inertial>
    <visual>
      <origin xyz="0 0 0.025" rpy="0 0 0"/>
      <geometry><box size="0.05 0.05 0.05"/></geometry>
    </visual>
  </link>

  <joint name="joint_1" type="revolute">
    <parent link="base_link"/>
    <child link="link_1"/>
    <origin xyz="0 0 0.1" rpy="0 0 0"/>
    <axis xyz="0 0 1"/>
    <limit lower="-3.14159" upper="3.14159" effort="100" velocity="1.5"/>
  </joint>

  <joint name="joint_2" type="revolute">
    <parent link="link_1"/>
    <child link="link_2"/>
    <origin xyz="0 0 0.3" rpy="0 0 0"/>
    <axis xyz="0 1 0"/>
    <limit lower="-1.57" upper="1.57" effort="50" velocity="2.0"/>
  </joint>

  <joint name="joint_ee" type="fixed">
    <parent link="link_2"/>
    <child link="ee_link"/>
    <origin xyz="0 0 0.25" rpy="0 0 0"/>
  </joint>
</robot>
